<?xml version="1.0" encoding="UTF-8"?>
<!-- Generated by org.testng.reporters.JUnitReportReporter -->
<testsuite hostname="PIO-L-4110" failures="0" tests="13" name="com.nucleus.qa.testcases.CoreSystemTesting" time="952.210" errors="1" timestamp="2024-10-01T19:57:08 IST" skipped="0">
  <testcase classname="com.nucleus.qa.testcases.CoreSystemTesting" name="TestCase12" time="43.659"/>
  <testcase classname="com.nucleus.qa.testcases.CoreSystemTesting" name="Exit" time="3.262">
    <error message="C:\Users\ShahrukhAata_l4\Project\Test\TestData\TestData.xls (The process cannot access the file because it is being used by another process)" type="java.io.FileNotFoundException">
      <![CDATA[java.io.FileNotFoundException: C:\Users\ShahrukhAata_l4\Project\Test\TestData\TestData.xls (The process cannot access the file because it is being used by another process)
at java.base/java.io.FileOutputStream.open0(Native Method)
at java.base/java.io.FileOutputStream.open(FileOutputStream.java:293)
at java.base/java.io.FileOutputStream.<init>(FileOutputStream.java:235)
at java.base/java.io.FileOutputStream.<init>(FileOutputStream.java:123)
at com.nucleus.qa.testcases.WriteCode.Write(WriteCode.java:45)
at com.nucleus.qa.testcases.CoreSystemTesting.Exit(CoreSystemTesting.java:3184)
at java.base/jdk.internal.reflect.NativeMethodAccessorImpl.invoke0(Native Method)
at java.base/jdk.internal.reflect.NativeMethodAccessorImpl.invoke(NativeMethodAccessorImpl.java:77)
at java.base/jdk.internal.reflect.DelegatingMethodAccessorImpl.invoke(DelegatingMethodAccessorImpl.java:43)
at java.base/java.lang.reflect.Method.invoke(Method.java:568)
at org.testng.internal.invokers.MethodInvocationHelper.invokeMethod(MethodInvocationHelper.java:141)
at org.testng.internal.invokers.MethodInvocationHelper.invokeMethodConsideringTimeout(MethodInvocationHelper.java:71)
at org.testng.internal.invokers.ConfigInvoker.invokeConfigurationMethod(ConfigInvoker.java:400)
at org.testng.internal.invokers.ConfigInvoker.invokeConfigurations(ConfigInvoker.java:333)
at org.testng.SuiteRunner.privateRun(SuiteRunner.java:386)
at org.testng.SuiteRunner.run(SuiteRunner.java:312)
at org.testng.SuiteRunnerWorker.runSuite(SuiteRunnerWorker.java:52)
at org.testng.SuiteRunnerWorker.run(SuiteRunnerWorker.java:95)
at org.testng.TestNG.runSuitesSequentially(TestNG.java:1274)
at org.testng.TestNG.runSuitesLocally(TestNG.java:1208)
at org.testng.TestNG.runSuites(TestNG.java:1112)
at org.testng.TestNG.run(TestNG.java:1079)
at com.nucleus.qa.testcases.Runner.main(Runner.java:28)
]]>
    </error>
  </testcase> <!-- Exit -->
  <testcase classname="com.nucleus.qa.testcases.CoreSystemTesting" name="TestCase10" time="80.130"/>
  <testcase classname="com.nucleus.qa.testcases.CoreSystemTesting" name="TestCase8" time="55.493"/>
  <testcase classname="com.nucleus.qa.testcases.CoreSystemTesting" name="TestCase4" time="62.851"/>
  <testcase classname="com.nucleus.qa.testcases.CoreSystemTesting" name="TestCase1" time="46.565"/>
  <testcase classname="com.nucleus.qa.testcases.CoreSystemTesting" name="TestCase2" time="197.180"/>
  <testcase classname="com.nucleus.qa.testcases.CoreSystemTesting" name="TestCase7" time="49.718"/>
  <testcase classname="com.nucleus.qa.testcases.CoreSystemTesting" name="TestCase3" time="192.254"/>
  <testcase classname="com.nucleus.qa.testcases.CoreSystemTesting" name="TestCase11" time="40.778"/>
  <testcase classname="com.nucleus.qa.testcases.CoreSystemTesting" name="TestCase5" time="61.816"/>
  <testcase classname="com.nucleus.qa.testcases.CoreSystemTesting" name="TestCase9" time="65.972"/>
  <testcase classname="com.nucleus.qa.testcases.CoreSystemTesting" name="TestCase6" time="52.532"/>
</testsuite> <!-- com.nucleus.qa.testcases.CoreSystemTesting -->
