<?xml version="1.0" encoding="UTF-8"?>
<!-- Generated by org.testng.reporters.JUnitReportReporter -->
<testsuite hostname="PIO-L-4110" failures="0" tests="2" name="com.nucleus.qa.testcases.Runner" time="38.888" errors="1" timestamp="2024-09-24T19:13:23 IST" skipped="0">
  <testcase classname="com.nucleus.qa.testcases.Runner" name="Exit" time="3.477">
    <error message="C:\Users\ShahrukhAata_l4\Project\Test\TestData\TestData.xls (The process cannot access the file because it is being used by another process)" type="java.io.FileNotFoundException">
      <![CDATA[java.io.FileNotFoundException: C:\Users\ShahrukhAata_l4\Project\Test\TestData\TestData.xls (The process cannot access the file because it is being used by another process)
at java.base/java.io.FileOutputStream.open0(Native Method)
at java.base/java.io.FileOutputStream.open(FileOutputStream.java:293)
at java.base/java.io.FileOutputStream.<init>(FileOutputStream.java:235)
at java.base/java.io.FileOutputStream.<init>(FileOutputStream.java:123)
at com.nucleus.qa.testcases.WriteCode.Write(WriteCode.java:47)
at com.nucleus.qa.testcases.CoreSystemTesting.Exit(CoreSystemTesting.java:2318)
at java.base/jdk.internal.reflect.NativeMethodAccessorImpl.invoke0(Native Method)
at java.base/jdk.internal.reflect.NativeMethodAccessorImpl.invoke(NativeMethodAccessorImpl.java:77)
at java.base/jdk.internal.reflect.DelegatingMethodAccessorImpl.invoke(DelegatingMethodAccessorImpl.java:43)
at java.base/java.lang.reflect.Method.invoke(Method.java:568)
at org.testng.internal.invokers.MethodInvocationHelper.invokeMethod(MethodInvocationHelper.java:141)
at org.testng.internal.invokers.MethodInvocationHelper.invokeMethodConsideringTimeout(MethodInvocationHelper.java:71)
at org.testng.internal.invokers.ConfigInvoker.invokeConfigurationMethod(ConfigInvoker.java:400)
at org.testng.internal.invokers.ConfigInvoker.invokeConfigurations(ConfigInvoker.java:333)
at org.testng.SuiteRunner.privateRun(SuiteRunner.java:386)
at org.testng.SuiteRunner.run(SuiteRunner.java:312)
at org.testng.SuiteRunnerWorker.runSuite(SuiteRunnerWorker.java:52)
at org.testng.SuiteRunnerWorker.run(SuiteRunnerWorker.java:95)
at org.testng.TestNG.runSuitesSequentially(TestNG.java:1274)
at org.testng.TestNG.runSuitesLocally(TestNG.java:1208)
at org.testng.TestNG.runSuites(TestNG.java:1112)
at org.testng.TestNG.run(TestNG.java:1079)
at org.testng.remote.AbstractRemoteTestNG.run(AbstractRemoteTestNG.java:115)
at org.testng.remote.RemoteTestNG.initAndRun(RemoteTestNG.java:293)
at org.testng.remote.RemoteTestNG.main(RemoteTestNG.java:91)
]]>
    </error>
  </testcase> <!-- Exit -->
  <testcase classname="com.nucleus.qa.testcases.Runner" name="TestCase1" time="35.411"/>
</testsuite> <!-- com.nucleus.qa.testcases.Runner -->
